Workbook

Sheet z3
A1: file | B1: mode | C1: rule | D1: result | E1: duration
A2: ALMI/ALMI.sleec | B2: concern | C2: 0 | D2: sat | E2: 0.20701217651367188
A3: ALMI/ALMI.sleec | B3: concern | C3: 1 | D3: unsat | E3: 0.3667585849761963
A4: ALMI/ALMI.sleec | B4: concern | C4: 2 | D4: unsat | E4: 0.3419318199157715
A5: ALMI/ALMI.sleec | B5: concern | C5: 3 | D5: sat | E5: 0.31687402725219727
A6: ALMI/ALMI.sleec | B6: concern | C6: 4 | D6: unsat | E6: 0.21298789978027344
A7: ALMI/ALMI.sleec | B7: concern | C7: 5 | D7: unsat | E7: 0.20846319198608398
A8: ALMI/ALMI.sleec | B8: concern | C8: 6 | D8: unsat | E8: 0.18791699409484863
A9: ALMI/ALMI.sleec | B9: concern | C9: 7 | D9: unsat | E9: 0.3721189498901367
A10: ALMI/ALMI.sleec | B10: concern | C10: 8 | D10: unsat | E10: 0.2248392105102539
A11: ALMI/ALMI.sleec | B11: concern | C11: 9 | D11: unsat | E11: 1.1292846202850342
A12: ALMI/ALMI.sleec | B12: concern | C12: 10 | D12: unsat | E12: 0.4296562671661377
A13: ALMI/ALMI.sleec | B13: conflict | C13: 0 | D13: sat | E13: 0.29523682594299316
... A1363: test4.sleec | B1363: redundancy | C1363: 2 | D1363: sat | E1363: 0.02353072166442871

Sheet filter
A1: file | B1: mode | C1: rule | D1: result | E1: duration
A2: test1.sleec | B2: redundancy | C2: 1 | D2: sat | E2: 0.009383201599121094
A3: test4.sleec | B3: redundancy | C3: 2 | D3: sat | E3: 0.009657144546508789
A4: test3.sleec | B4: redundancy | C4: 2 | D4: sat | E4: 0.00982046127319336
A5: test.sleec | B5: redundancy | C5: 2 | D5: unsat | E5: 0.013736724853515625
A6: test.sleec | B6: redundancy | C6: 1 | D6: unsat | E6: 0.013898849487304688
A7: test1.sleec | B7: redundancy | C7: 0 | D7: sat | E7: 0.015358924865722656
A8: test1.sleec | B8: redundancy | C8: 2 | D8: unsat | E8: 0.01582789421081543
A9: test1.sleec | B9: conflict | C9: 1 | D9: sat | E9: 0.017138004302978516
A10: test4.sleec | B10: redundancy | C10: 1 | D10: sat | E10: 0.01734185218811035
A11: test2.sleec | B11: redundancy | C11: 1 | D11: sat | E11: 0.017393827438354492
A12: test3.sleec | B12: redundancy | C12: 1 | D12: sat | E12: 0.017560243606567383
A13: test.sleec | B13: redundancy | C13: 7 | D13: unsat | E13: 0.018093585968017578
... A1363: covidfree/covidfree.sleec | B1363: redundancy | C1363: 17 | D1363: unknown (TIMEOUT) | E1363: 20.068293809890747

Sheet setall
A1: file | B1: mode | C1: rule | D1: result | E1: duration | F1: Column1
A2: test1.sleec | B2: redundancy | C2: 1 | D2: sat | E2: 0.010376692 | F2: =AND('z3'!A1341=setall!A1341,'z3'!B1341=setall!B1341, 'z3'!C1341=setall!C1341, 'z3'!D1341=setall!D1341) -> FALSE
A3: test3.sleec | B3: redundancy | C3: 2 | D3: sat | E3: 0.010629177 | F3: =AND('z3'!A1356=setall!A1356,'z3'!B1356=setall!B1356, 'z3'!C1356=setall!C1356, 'z3'!D1356=setall!D1356) -> FALSE
A4: test4.sleec | B4: redundancy | C4: 2 | D4: sat | E4: 0.010863543 | F4: =AND('z3'!A1363=setall!A1363,'z3'!B1363=setall!B1363, 'z3'!C1363=setall!C1363, 'z3'!D1363=setall!D1363) -> FALSE
A5: test.sleec | B5: redundancy | C5: 1 | D5: unsat | E5: 0.014583826 | F5: =AND('z3'!A1316=setall!A1316,'z3'!B1316=setall!B1316, 'z3'!C1316=setall!C1316, 'z3'!D1316=setall!D1316) -> FALSE
A6: test.sleec | B6: redundancy | C6: 2 | D6: unsat | E6: 0.014737606 | F6: =AND('z3'!A1317=setall!A1317,'z3'!B1317=setall!B1317, 'z3'!C1317=setall!C1317, 'z3'!D1317=setall!D1317) -> FALSE
A7: test1.sleec | B7: redundancy | C7: 0 | D7: sat | E7: 0.017042398 | F7: =AND('z3'!A1340=setall!A1340,'z3'!B1340=setall!B1340, 'z3'!C1340=setall!C1340, 'z3'!D1340=setall!D1340) -> FALSE
A8: test1.sleec | B8: redundancy | C8: 2 | D8: unsat | E8: 0.017447472 | F8: =AND('z3'!A1342=setall!A1342,'z3'!B1342=setall!B1342, 'z3'!C1342=setall!C1342, 'z3'!D1342=setall!D1342) -> FALSE
A9: test1.sleec | B9: conflict | C9: 1 | D9: sat | E9: 0.018088341 | F9: =AND('z3'!A1337=setall!A1337,'z3'!B1337=setall!B1337, 'z3'!C1337=setall!C1337, 'z3'!D1337=setall!D1337) -> FALSE
A10: test3.sleec | B10: redundancy | C10: 1 | D10: sat | E10: 0.018536568 | F10: =AND('z3'!A1355=setall!A1355,'z3'!B1355=setall!B1355, 'z3'!C1355=setall!C1355, 'z3'!D1355=setall!D1355) -> FALSE
A11: test2.sleec | B11: redundancy | C11: 1 | D11: sat | E11: 0.01864934 | F11: =AND('z3'!A1348=setall!A1348,'z3'!B1348=setall!B1348, 'z3'!C1348=setall!C1348, 'z3'!D1348=setall!D1348) -> FALSE
A12: test4.sleec | B12: redundancy | C12: 1 | D12: sat | E12: 0.01898098 | F12: =AND('z3'!A1362=setall!A1362,'z3'!B1362=setall!B1362, 'z3'!C1362=setall!C1362, 'z3'!D1362=setall!D1362) -> FALSE
A13: test.sleec | B13: redundancy | C13: 7 | D13: unsat | E13: 0.019583941 | F13: =AND('z3'!A1322=setall!A1322,'z3'!B1322=setall!B1322, 'z3'!C1322=setall!C1322, 'z3'!D1322=setall!D1322) -> FALSE
A14: buggy.sleec | B14: redundancy | C14: 7 | D14: sat | E14: 0.019720793 | F14: =AND('z3'!A603=setall!A603,'z3'!B603=setall!B603, 'z3'!C603=setall!C603, 'z3'!D603=setall!D603) -> FALSE
A15: covidfree/covidfree.sleec | B15: redundancy | C15: 5 | D15: unsat | E15: 0.020329475 | F15: =AND('z3'!A638=setall!A638,'z3'!B638=setall!B638, 'z3'!C638=setall!C638, 'z3'!D638=setall!D638) -> FALSE
A16: Autocar/Autocar.sleec | B16: concern | C16: 8 | D16: unsat | E16: 0.020431757 | F16: =AND('z3'!A281=setall!A281,'z3'!B281=setall!B281, 'z3'!C281=setall!C281, 'z3'!D281=setall!D281) -> FALSE
A17: test3.sleec | B17: redundancy | C17: 0 | D17: sat | E17: 0.020514727 | F17: =AND('z3'!A1354=setall!A1354,'z3'!B1354=setall!B1354, 'z3'!C1354=setall!C1354, 'z3'!D1354=setall!D1354) -> FALSE
A18: test4.sleec | B18: conflict | C18: 2 | D18: sat | E18: 0.02089262 | F18: =AND('z3'!A1360=setall!A1360,'z3'!B1360=setall!B1360, 'z3'!C1360=setall!C1360, 'z3'!D1360=setall!D1360) -> FALSE
A19: test3.sleec | B19: conflict | C19: 2 | D19: sat | E19: 0.021039963 | F19: =AND('z3'!A1353=setall!A1353,'z3'!B1353=setall!B1353, 'z3'!C1353=setall!C1353, 'z3'!D1353=setall!D1353) -> FALSE
A20: test4.sleec | B20: redundancy | C20: 0 | D20: sat | E20: 0.021095753 | F20: =AND('z3'!A1361=setall!A1361,'z3'!B1361=setall!B1361, 'z3'!C1361=setall!C1361, 'z3'!D1361=setall!D1361) -> FALSE
A21: Autocar/Autocar-corrected.sleec | B21: concern | C21: 8 | D21: unsat | E21: 0.02110076 | F21: =AND('z3'!A347=setall!A347,'z3'!B347=setall!B347, 'z3'!C347=setall!C347, 'z3'!D347=setall!D347) -> FALSE
A22: test.sleec | B22: conflict | C22: 15 | D22: sat | E22: 0.021174908 | F22: =AND('z3'!A1309=setall!A1309,'z3'!B1309=setall!B1309, 'z3'!C1309=setall!C1309, 'z3'!D1309=setall!D1309) -> FALSE
A23: test.sleec | B23: redundancy | C23: 18 | D23: sat | E23: 0.021214247 | F23: =AND('z3'!A1333=setall!A1333,'z3'!B1333=setall!B1333, 'z3'!C1333=setall!C1333, 'z3'!D1333=setall!D1333) -> FALSE
A24: test.sleec | B24: conflict | C24: 16 | D24: sat | E24: 0.021267414 | F24: =AND('z3'!A1310=setall!A1310,'z3'!B1310=setall!B1310, 'z3'!C1310=setall!C1310, 'z3'!D1310=setall!D1310) -> FALSE
A25: test.sleec | B25: conflict | C25: 13 | D25: sat | E25: 0.021978378 | F25: =AND('z3'!A1307=setall!A1307,'z3'!B1307=setall!B1307, 'z3'!C1307=setall!C1307, 'z3'!D1307=setall!D1307) -> FALSE
A26: test2.sleec | B26: redundancy | C26: 0 | D26: sat | E26: 0.021979332 | F26: =AND('z3'!A1347=setall!A1347,'z3'!B1347=setall!B1347, 'z3'!C1347=setall!C1347, 'z3'!D1347=setall!D1347) -> FALSE
A27: buggy.sleec | B27: redundancy | C27: 5 | D27: unsat | E27: 0.022402763 | F27: =AND('z3'!A601=setall!A601,'z3'!B601=setall!B601, 'z3'!C601=setall!C601, 'z3'!D601=setall!D601) -> FALSE
A28: buggy.sleec | B28: redundancy | C28: 8 | D28: sat | E28: 0.022742271 | F28: =AND('z3'!A604=setall!A604,'z3'!B604=setall!B604, 'z3'!C604=setall!C604, 'z3'!D604=setall!D604) -> FALSE
A29: test.sleec | B29: conflict | C29: 14 | D29: sat | E29: 0.02496767 | F29: =AND('z3'!A1308=setall!A1308,'z3'!B1308=setall!B1308, 'z3'!C1308=setall!C1308, 'z3'!D1308=setall!D1308) -> FALSE
A30: test.sleec | B30: redundancy | C30: 3 | D30: sat | E30: 0.025224209 | F30: =AND('z3'!A1318=setall!A1318,'z3'!B1318=setall!B1318, 'z3'!C1318=setall!C1318, 'z3'!D1318=setall!D1318) -> FALSE
A31: test.sleec | B31: redundancy | C31: 15 | D31: sat | E31: 0.025278568 | F31: =AND('z3'!A1330=setall!A1330,'z3'!B1330=setall!B1330, 'z3'!C1330=setall!C1330, 'z3'!D1330=setall!D1330) -> FALSE
A32: test.sleec | B32: redundancy | C32: 4 | D32: unsat | E32: 0.025580645 | F32: =AND('z3'!A1319=setall!A1319,'z3'!B1319=setall!B1319, 'z3'!C1319=setall!C1319, 'z3'!D1319=setall!D1319) -> FALSE
A33: buggy.sleec | B33: redundancy | C33: 11 | D33: sat | E33: 0.026266813 | F33: =AND('z3'!A607=setall!A607,'z3'!B607=setall!B607, 'z3'!C607=setall!C607, 'z3'!D607=setall!D607) -> FALSE
A34: test2.sleec | B34: redundancy | C34: 2 | D34: sat | E34: 0.027121782 | F34: =AND('z3'!A1349=setall!A1349,'z3'!B1349=setall!B1349, 'z3'!C1349=setall!C1349, 'z3'!D1349=setall!D1349) -> FALSE
A35: DAISY/Daisy.sleec | B35: redundancy | C35: 19 | D35: unsat | E35: 0.029021502 | F35: =AND('z3'!A854=setall!A854,'z3'!B854=setall!B854, 'z3'!C854=setall!C854, 'z3'!D854=setall!D854) -> FALSE
A36: test1.sleec | B36: redundancy | C36: 3 | D36: sat | E36: 0.029343367 | F36: =AND('z3'!A1343=setall!A1343,'z3'!B1343=setall!B1343, 'z3'!C1343=setall!C1343, 'z3'!D1343=setall!D1343) -> FALSE
A37: buggy.sleec | B37: redundancy | C37: 9 | D37: sat | E37: 0.029772043 | F37: =AND('z3'!A605=setall!A605,'z3'!B605=setall!B605, 'z3'!C605=setall!C605, 'z3'!D605=setall!D605) -> FALSE
A38: covidfree/manual.sleec | B38: redundancy | C38: 14 | D38: sat | E38: 0.02996254 | F38: =AND('z3'!A691=setall!A691,'z3'!B691=setall!B691, 'z3'!C691=setall!C691, 'z3'!D691=setall!D691) -> FALSE
A39: CSI/CSI.sleec | B39: concern | C39: 7 | D39: unsat | E39: 0.030085564 | F39: =AND('z3'!A703=setall!A703,'z3'!B703=setall!B703, 'z3'!C703=setall!C703, 'z3'!D703=setall!D703) -> FALSE
A40: covidfree/manual.sleec | B40: redundancy | C40: 4 | D40: sat | E40: 0.030339956 | F40: =AND('z3'!A681=setall!A681,'z3'!B681=setall!B681, 'z3'!C681=setall!C681, 'z3'!D681=setall!D681) -> FALSE
...

Sheet quantifiers (fmf)
A1: file | B1: mode | C1: rule | D1: result | E1: duration
A2: DAISY/Daisy.sleec | B2: redundancy | C2: 19 | D2: unsat | E2: 0.009747982025146484
A3: test1.sleec | B3: redundancy | C3: 1 | D3: sat | E3: 0.01358795166015625
A4: test4.sleec | B4: redundancy | C4: 2 | D4: sat | E4: 0.014086246490478516
A5: test3.sleec | B5: redundancy | C5: 2 | D5: sat | E5: 0.014117002487182617
A6: test1.sleec | B6: redundancy | C6: 0 | D6: sat | E6: 0.01800990104675293
A7: test4.sleec | B7: conflict | C7: 2 | D7: sat | E7: 0.018881797790527344
A8: test3.sleec | B8: conflict | C8: 2 | D8: sat | E8: 0.019309043884277344
A9: test1.sleec | B9: conflict | C9: 1 | D9: sat | E9: 0.020095109939575195
A10: test2.sleec | B10: redundancy | C10: 2 | D10: sat | E10: 0.021628379821777344
A11: buggy.sleec | B11: redundancy | C11: 8 | D11: sat | E11: 0.026772022247314453
A12: test.sleec | B12: redundancy | C12: 18 | D12: sat | E12: 0.028182506561279297
A13: test.sleec | B13: conflict | C13: 16 | D13: sat | E13: 0.028985023498535156
... A1363: test4.sleec | B1363: concern | C1363: 0 | D1363: unknown (TIMEOUT) | E1363: 20.005602836608887

Sheet quantifiers (enum-inst)
A1: file | B1: mode | C1: rule | D1: result | E1: duration
A2: ALMI/ALMI.sleec | B2: redundancy | C2: 0 | D2: unknown (TIMEOUT) | E2: 20.000283002853394
A3: ALMI/ALMI.sleec | B3: redundancy | C3: 1 | D3: unknown (TIMEOUT) | E3: 20.00025510787964
A4: ALMI/ALMI.sleec | B4: redundancy | C4: 2 | D4: unknown (TIMEOUT) | E4: 20.012873649597168
A5: ALMI/ALMI.sleec | B5: redundancy | C5: 3 | D5: unknown (TIMEOUT) | E5: 20.01119041442871
A6: ALMI/ALMI.sleec | B6: redundancy | C6: 4 | D6: unknown (TIMEOUT) | E6: 20.000587463378906
A7: ALMI/ALMI.sleec | B7: redundancy | C7: 5 | D7: unknown (TIMEOUT) | E7: 20.01057243347168
A8: ALMI/ALMI.sleec | B8: redundancy | C8: 6 | D8: unknown (TIMEOUT) | E8: 20.003586530685425
A9: ALMI/ALMI.sleec | B9: redundancy | C9: 7 | D9: unknown (TIMEOUT) | E9: 20.163753271102905
A10: ALMI/ALMI.sleec | B10: redundancy | C10: 8 | D10: unknown (TIMEOUT) | E10: 20.050167560577393
A11: ALMI/ALMI.sleec | B11: redundancy | C11: 9 | D11: unknown (TIMEOUT) | E11: 20.00010323524475
A12: ALMI/ALMI.sleec | B12: redundancy | C12: 10 | D12: unknown (TIMEOUT) | E12: 20.054643392562866
A13: ALMI/ALMI.sleec | B13: redundancy | C13: 11 | D13: unknown (TIMEOUT) | E13: 20.000078439712524
... A1363: test4.sleec | B1363: concern | C1363: 0 | D1363: unsat | E1363: 0.21202850341796875

Sheet comparisons
A1: filter match z3 | B1: quantifiers(fmf) match z3 | C1: quantifiers(enum-inst) match z4
A2: =AND(Table3[[#This Row],[file]]=Table2[[#This Row],[file]], Table2[[#This Row],[mode]] = Table3[[#This Row],[mode]], Table3[[#This Row],[rule]] = Table2[[#This Row],[rule]], OR(ISNUMBER(SEARCH("unknown",Table2[[#This Row],[result]])), Table2[[#This Row],[result]] = Table3[[#This Row],[result]])) -> FALSE | B2: =AND(Table3[[#This Row],[file]]=Table1[[#This Row],[file]], Table1[[#This Row],[mode]] = Table3[[#This Row],[mode]], Table3[[#This Row],[rule]] = Table1[[#This Row],[rule]], OR(ISNUMBER(SEARCH("unknown",Table1[[#This Row],[result]])), Table1[[#This Row],[result]] = Table3[[#This Row],[result]])) -> FALSE | C2: =AND(Table3[[#This Row],[file]]=Table5[[#This Row],[file]], Table5[[#This Row],[mode]] = Table3[[#This Row],[mode]], Table3[[#This Row],[rule]] = Table5[[#This Row],[rule]], OR(ISNUMBER(SEARCH("unknown",Table5[[#This Row],[result]])), Table5[[#This Row],[result]] = Table3[[#This Row],[result]])) -> FALSE
A3: =AND(Table3[[#This Row],[file]]=Table2[[#This Row],[file]], Table2[[#This Row],[mode]] = Table3[[#This Row],[mode]], Table3[[#This Row],[rule]] = Table2[[#This Row],[rule]], OR(ISNUMBER(SEARCH("unknown",Table2[[#This Row],[result]])), Table2[[#This Row],[result]] = Table3[[#This Row],[result]])) -> FALSE | B3: =AND(Table3[[#This Row],[file]]=Table1[[#This Row],[file]], Table1[[#This Row],[mode]] = Table3[[#This Row],[mode]], Table3[[#This Row],[rule]] = Table1[[#This Row],[rule]], OR(ISNUMBER(SEARCH("unknown",Table1[[#This Row],[result]])), Table1[[#This Row],[result]] = Table3[[#This Row],[result]])) -> FALSE | C3: =AND(Table3[[#This Row],[file]]=Table5[[#This Row],[file]], Table5[[#This Row],[mode]] = Table3[[#This Row],[mode]], Table3[[#This Row],[rule]] = Table5[[#This Row],[rule]], OR(ISNUMBER(SEARCH("unknown",Table5[[#This Row],[result]])), Table5[[#This Row],[result]] = Table3[[#This Row],[result]])) -> FALSE
A4: =AND(Table3[[#This Row],[file]]=Table2[[#This Row],[file]], Table2[[#This Row],[mode]] = Table3[[#This Row],[mode]], Table3[[#This Row],[rule]] = Table2[[#This Row],[rule]], OR(ISNUMBER(SEARCH("unknown",Table2[[#This Row],[result]])), Table2[[#This Row],[result]] = Table3[[#This Row],[result]])) -> FALSE | B4: =AND(Table3[[#This Row],[file]]=Table1[[#This Row],[file]], Table1[[#This Row],[mode]] = Table3[[#This Row],[mode]], Table3[[#This Row],[rule]] = Table1[[#This Row],[rule]], OR(ISNUMBER(SEARCH("unknown",Table1[[#This Row],[result]])), Table1[[#This Row],[result]] = Table3[[#This Row],[result]])) -> FALSE | C4: =AND(Table3[[#This Row],[file]]=Table5[[#This Row],[file]], Table5[[#This Row],[mode]] = Table3[[#This Row],[mode]], Table3[[#This Row],[rule]] = Table5[[#This Row],[rule]], OR(ISNUMBER(SEARCH("unknown",Table5[[#This Row],[result]])), Table5[[#This Row],[result]] = Table3[[#This Row],[result]])) -> FALSE
A5: =AND(Table3[[#This Row],[file]]=Table2[[#This Row],[file]], Table2[[#This Row],[mode]] = Table3[[#This Row],[mode]], Table3[[#This Row],[rule]] = Table2[[#This Row],[rule]], OR(ISNUMBER(SEARCH("unknown",Table2[[#This Row],[result]])), Table2[[#This Row],[result]] = Table3[[#This Row],[result]])) -> FALSE | B5: =AND(Table3[[#This Row],[file]]=Table1[[#This Row],[file]], Table1[[#This Row],[mode]] = Table3[[#This Row],[mode]], Table3[[#This Row],[rule]] = Table1[[#This Row],[rule]], OR(ISNUMBER(SEARCH("unknown",Table1[[#This Row],[result]])), Table1[[#This Row],[result]] = Table3[[#This Row],[result]])) -> FALSE | C5: =AND(Table3[[#This Row],[file]]=Table5[[#This Row],[file]], Table5[[#This Row],[mode]] = Table3[[#This Row],[mode]], Table3[[#This Row],[rule]] = Table5[[#This Row],[rule]], OR(ISNUMBER(SEARCH("unknown",Table5[[#This Row],[result]])), Table5[[#This Row],[result]] = Table3[[#This Row],[result]])) -> FALSE
A6: =AND(Table3[[#This Row],[file]]=Table2[[#This Row],[file]], Table2[[#This Row],[mode]] = Table3[[#This Row],[mode]], Table3[[#This Row],[rule]] = Table2[[#This Row],[rule]], OR(ISNUMBER(SEARCH("unknown",Table2[[#This Row],[result]])), Table2[[#This Row],[result]] = Table3[[#This Row],[result]])) -> FALSE | B6: =AND(Table3[[#This Row],[file]]=Table1[[#This Row],[file]], Table1[[#This Row],[mode]] = Table3[[#This Row],[mode]], Table3[[#This Row],[rule]] = Table1[[#This Row],[rule]], OR(ISNUMBER(SEARCH("unknown",Table1[[#This Row],[result]])), Table1[[#This Row],[result]] = Table3[[#This Row],[result]])) -> FALSE | C6: =AND(Table3[[#This Row],[file]]=Table5[[#This Row],[file]], Table5[[#This Row],[mode]] = Table3[[#This Row],[mode]], Table3[[#This Row],[rule]] = Table5[[#This Row],[rule]], OR(ISNUMBER(SEARCH("unknown",Table5[[#This Row],[result]])), Table5[[#This Row],[result]] = Table3[[#This Row],[result]])) -> FALSE
A7: =AND(Table3[[#This Row],[file]]=Table2[[#This Row],[file]], Table2[[#This Row],[mode]] = Table3[[#This Row],[mode]], Table3[[#This Row],[rule]] = Table2[[#This Row],[rule]], OR(ISNUMBER(SEARCH("unknown",Table2[[#This Row],[result]])), Table2[[#This Row],[result]] = Table3[[#This Row],[result]])) -> FALSE | B7: =AND(Table3[[#This Row],[file]]=Table1[[#This Row],[file]], Table1[[#This Row],[mode]] = Table3[[#This Row],[mode]], Table3[[#This Row],[rule]] = Table1[[#This Row],[rule]], OR(ISNUMBER(SEARCH("unknown",Table1[[#This Row],[result]])), Table1[[#This Row],[result]] = Table3[[#This Row],[result]])) -> FALSE | C7: =AND(Table3[[#This Row],[file]]=Table5[[#This Row],[file]], Table5[[#This Row],[mode]] = Table3[[#This Row],[mode]], Table3[[#This Row],[rule]] = Table5[[#This Row],[rule]], OR(ISNUMBER(SEARCH("unknown",Table5[[#This Row],[result]])), Table5[[#This Row],[result]] = Table3[[#This Row],[result]])) -> FALSE
A8: =AND(Table3[[#This Row],[file]]=Table2[[#This Row],[file]], Table2[[#This Row],[mode]] = Table3[[#This Row],[mode]], Table3[[#This Row],[rule]] = Table2[[#This Row],[rule]], OR(ISNUMBER(SEARCH("unknown",Table2[[#This Row],[result]])), Table2[[#This Row],[result]] = Table3[[#This Row],[result]])) -> FALSE | B8: =AND(Table3[[#This Row],[file]]=Table1[[#This Row],[file]], Table1[[#This Row],[mode]] = Table3[[#This Row],[mode]], Table3[[#This Row],[rule]] = Table1[[#This Row],[rule]], OR(ISNUMBER(SEARCH("unknown",Table1[[#This Row],[result]])), Table1[[#This Row],[result]] = Table3[[#This Row],[result]])) -> FALSE | C8: =AND(Table3[[#This Row],[file]]=Table5[[#This Row],[file]], Table5[[#This Row],[mode]] = Table3[[#This Row],[mode]], Table3[[#This Row],[rule]] = Table5[[#This Row],[rule]], OR(ISNUMBER(SEARCH("unknown",Table5[[#This Row],[result]])), Table5[[#This Row],[result]] = Table3[[#This Row],[result]])) -> FALSE
A9: =AND(Table3[[#This Row],[file]]=Table2[[#This Row],[file]], Table2[[#This Row],[mode]] = Table3[[#This Row],[mode]], Table3[[#This Row],[rule]] = Table2[[#This Row],[rule]], OR(ISNUMBER(SEARCH("unknown",Table2[[#This Row],[result]])), Table2[[#This Row],[result]] = Table3[[#This Row],[result]])) -> FALSE | B9: =AND(Table3[[#This Row],[file]]=Table1[[#This Row],[file]], Table1[[#This Row],[mode]] = Table3[[#This Row],[mode]], Table3[[#This Row],[rule]] = Table1[[#This Row],[rule]], OR(ISNUMBER(SEARCH("unknown",Table1[[#This Row],[result]])), Table1[[#This Row],[result]] = Table3[[#This Row],[result]])) -> FALSE | C9: =AND(Table3[[#This Row],[file]]=Table5[[#This Row],[file]], Table5[[#This Row],[mode]] = Table3[[#This Row],[mode]], Table3[[#This Row],[rule]] = Table5[[#This Row],[rule]], OR(ISNUMBER(SEARCH("unknown",Table5[[#This Row],[result]])), Table5[[#This Row],[result]] = Table3[[#This Row],[result]])) -> FALSE
A10: =AND(Table3[[#This Row],[file]]=Table2[[#This Row],[file]], Table2[[#This Row],[mode]] = Table3[[#This Row],[mode]], Table3[[#This Row],[rule]] = Table2[[#This Row],[rule]], OR(ISNUMBER(SEARCH("unknown",Table2[[#This Row],[result]])), Table2[[#This Row],[result]] = Table3[[#This Row],[result]])) -> FALSE | B10: =AND(Table3[[#This Row],[file]]=Table1[[#This Row],[file]], Table1[[#This Row],[mode]] = Table3[[#This Row],[mode]], Table3[[#This Row],[rule]] = Table1[[#This Row],[rule]], OR(ISNUMBER(SEARCH("unknown",Table1[[#This Row],[result]])), Table1[[#This Row],[result]] = Table3[[#This Row],[result]])) -> FALSE | C10: =AND(Table3[[#This Row],[file]]=Table5[[#This Row],[file]], Table5[[#This Row],[mode]] = Table3[[#This Row],[mode]], Table3[[#This Row],[rule]] = Table5[[#This Row],[rule]], OR(ISNUMBER(SEARCH("unknown",Table5[[#This Row],[result]])), Table5[[#This Row],[result]] = Table3[[#This Row],[result]])) -> FALSE
A11: =AND(Table3[[#This Row],[file]]=Table2[[#This Row],[file]], Table2[[#This Row],[mode]] = Table3[[#This Row],[mode]], Table3[[#This Row],[rule]] = Table2[[#This Row],[rule]], OR(ISNUMBER(SEARCH("unknown",Table2[[#This Row],[result]])), Table2[[#This Row],[result]] = Table3[[#This Row],[result]])) -> FALSE | B11: =AND(Table3[[#This Row],[file]]=Table1[[#This Row],[file]], Table1[[#This Row],[mode]] = Table3[[#This Row],[mode]], Table3[[#This Row],[rule]] = Table1[[#This Row],[rule]], OR(ISNUMBER(SEARCH("unknown",Table1[[#This Row],[result]])), Table1[[#This Row],[result]] = Table3[[#This Row],[result]])) -> FALSE | C11: =AND(Table3[[#This Row],[file]]=Table5[[#This Row],[file]], Table5[[#This Row],[mode]] = Table3[[#This Row],[mode]], Table3[[#This Row],[rule]] = Table5[[#This Row],[rule]], OR(ISNUMBER(SEARCH("unknown",Table5[[#This Row],[result]])), Table5[[#This Row],[result]] = Table3[[#This Row],[result]])) -> FALSE
A12: =AND(Table3[[#This Row],[file]]=Table2[[#This Row],[file]], Table2[[#This Row],[mode]] = Table3[[#This Row],[mode]], Table3[[#This Row],[rule]] = Table2[[#This Row],[rule]], OR(ISNUMBER(SEARCH("unknown",Table2[[#This Row],[result]])), Table2[[#This Row],[result]] = Table3[[#This Row],[result]])) -> FALSE | B12: =AND(Table3[[#This Row],[file]]=Table1[[#This Row],[file]], Table1[[#This Row],[mode]] = Table3[[#This Row],[mode]], Table3[[#This Row],[rule]] = Table1[[#This Row],[rule]], OR(ISNUMBER(SEARCH("unknown",Table1[[#This Row],[result]])), Table1[[#This Row],[result]] = Table3[[#This Row],[result]])) -> FALSE | C12: =AND(Table3[[#This Row],[file]]=Table5[[#This Row],[file]], Table5[[#This Row],[mode]] = Table3[[#This Row],[mode]], Table3[[#This Row],[rule]] = Table5[[#This Row],[rule]], OR(ISNUMBER(SEARCH("unknown",Table5[[#This Row],[result]])), Table5[[#This Row],[result]] = Table3[[#This Row],[result]])) -> FALSE
A13: =AND(Table3[[#This Row],[file]]=Table2[[#This Row],[file]], Table2[[#This Row],[mode]] = Table3[[#This Row],[mode]], Table3[[#This Row],[rule]] = Table2[[#This Row],[rule]], OR(ISNUMBER(SEARCH("unknown",Table2[[#This Row],[result]])), Table2[[#This Row],[result]] = Table3[[#This Row],[result]])) -> FALSE | B13: =AND(Table3[[#This Row],[file]]=Table1[[#This Row],[file]], Table1[[#This Row],[mode]] = Table3[[#This Row],[mode]], Table3[[#This Row],[rule]] = Table1[[#This Row],[rule]], OR(ISNUMBER(SEARCH("unknown",Table1[[#This Row],[result]])), Table1[[#This Row],[result]] = Table3[[#This Row],[result]])) -> FALSE | C13: =AND(Table3[[#This Row],[file]]=Table5[[#This Row],[file]], Table5[[#This Row],[mode]] = Table3[[#This Row],[mode]], Table3[[#This Row],[rule]] = Table5[[#This Row],[rule]], OR(ISNUMBER(SEARCH("unknown",Table5[[#This Row],[result]])), Table5[[#This Row],[result]] = Table3[[#This Row],[result]])) -> FALSE
... A1363: =AND(Table3[[#This Row],[file]]=Table2[[#This Row],[file]], Table2[[#This Row],[mode]] = Table3[[#This Row],[mode]], Table3[[#This Row],[rule]] = Table2[[#This Row],[rule]], OR(ISNUMBER(SEARCH("unknown",Table2[[#This Row],[result]])), Table2[[#This Row],[result]] = Table3[[#This Row],[result]])) -> FALSE | B1363: =AND(Table3[[#This Row],[file]]=Table1[[#This Row],[file]], Table1[[#This Row],[mode]] = Table3[[#This Row],[mode]], Table3[[#This Row],[rule]] = Table1[[#This Row],[rule]], OR(ISNUMBER(SEARCH("unknown",Table1[[#This Row],[result]])), Table1[[#This Row],[result]] = Table3[[#This Row],[result]])) -> FALSE | C1363: =AND(Table3[[#This Row],[file]]=Table5[[#This Row],[file]], Table5[[#This Row],[mode]] = Table3[[#This Row],[mode]], Table3[[#This Row],[rule]] = Table5[[#This Row],[rule]], OR(ISNUMBER(SEARCH("unknown",Table5[[#This Row],[result]])), Table5[[#This Row],[result]] = Table3[[#This Row],[result]])) -> FALSE

Sheet cactus
A1: LEGOS | B1: filter | C1: fmf | D1: z3 predicates | E1: cvc5 predicates | F1: cvc5 predicate mbqi | G1: LEGOS | H1: setall | I1: fmf | J1: z3 predicates | K1: cvc5 predicates | L1: cvc5 predicats mbqi | M1: instance | N1: LEGOS | O1: instance | P1: setall | Q1: instance | R1: fmf | S1: instance | T1: z3 predicates | U1: instance | V1: cvc5 predicates | W1: instance | X1: cvc5 predicate mbqi
A2: 0.021044015884399414 | B2: 0.009383201599121094 | C2: 0.009747982025146484 | D2: 0.01 | E2: 0.022 | F2: 0.017 | G2: =VALUE(A2) -> 0.021044016 | H2: 0.010376692 | I2: =VALUE(C2) -> 0.009747982 | J2: =VALUE(D2) -> 0.01 | K2: =VALUE(E2) -> 0.022 | L2: =VALUE(F2) -> 0.017 | M2: 1 | N2: =G2 -> 0.021044016 | O2: 1 | P2: =H2 -> 0.010376692 | Q2: 1 | R2: =I2 -> 0.009747982 | S2: 1 | T2: =J2 -> 0.01 | U2: 1 | V2: =K2 -> 0.022 | W2: 1 | X2: =L2 -> 0.017
A3: 0.02345108985900879 | B3: 0.009657144546508789 | C3: 0.01358795166015625 | D3: 0.01 | E3: 0.032 | F3: 0.018 | G3: =VALUE(A3) -> 0.02345109 | H3: 0.010629177 | I3: =VALUE(C3) -> 0.013587952 | J3: =VALUE(D3) -> 0.01 | K3: =VALUE(E3) -> 0.032 | L3: =VALUE(F3) -> 0.018 | M3: =M2+1 -> 2 | N3: =SUM(G$2:G3) -> 0.044495106 | O3: =O2+1 -> 2 | P3: =SUM(H$2:H3) -> 0.021005869 | Q3: =Q2+1 -> 2 | R3: =SUM(I$2:I3) -> 0.023335934 | S3: =S2+1 -> 2 | T3: =SUM(J$2:J3) -> 0.02 | U3: =U2+1 -> 2 | V3: =SUM(K$2:K3) -> 0.054 | W3: 2 | X3: =SUM(L$2:L3) -> 0.035
A4: 0.02353072166442871 | B4: 0.00982046127319336 | C4: 0.014086246490478516 | D4: 0.01 | E4: 0.033 | F4: 0.019 | G4: =VALUE(A4) -> 0.023530722 | H4: 0.010863543 | I4: =VALUE(C4) -> 0.014086246 | J4: =VALUE(D4) -> 0.01 | K4: =VALUE(E4) -> 0.033 | L4: =VALUE(F4) -> 0.019 | M4: =M3+1 -> 3 | N4: =SUM(G$2:G4) -> 0.068025827 | O4: =O3+1 -> 3 | P4: =SUM(H$2:H4) -> 0.031869411 | Q4: =Q3+1 -> 3 | R4: =SUM(I$2:I4) -> 0.03742218 | S4: =S3+1 -> 3 | T4: =SUM(J$2:J4) -> 0.03 | U4: =U3+1 -> 3 | V4: =SUM(K$2:K4) -> 0.087 | W4: 3 | X4: =SUM(L$2:L4) -> 0.054
A5: 0.02353191375732422 | B5: 0.013736724853515625 | C5: 0.014117002487182617 | D5: 0.02 | E5: 0.036 | F5: 0.019 | G5: =VALUE(A5) -> 0.023531914 | H5: 0.014583826 | I5: =VALUE(C5) -> 0.014117002 | J5: =VALUE(D5) -> 0.02 | K5: =VALUE(E5) -> 0.036 | L5: =VALUE(F5) -> 0.019 | M5: =M4+1 -> 4 | N5: =SUM(G$2:G5) -> 0.091557741 | O5: =O4+1 -> 4 | P5: =SUM(H$2:H5) -> 0.046453238 | Q5: =Q4+1 -> 4 | R5: =SUM(I$2:I5) -> 0.051539183 | S5: =S4+1 -> 4 | T5: =SUM(J$2:J5) -> 0.05 | U5: =U4+1 -> 4 | V5: =SUM(K$2:K5) -> 0.123 | W5: 4 | X5: =SUM(L$2:L5) -> 0.073
A6: 0.02717733383178711 | B6: 0.013898849487304688 | C6: 0.01800990104675293 | D6: 0.02 | E6: 0.036 | F6: 0.019 | G6: =VALUE(A6) -> 0.027177334 | H6: 0.014737606 | I6: =VALUE(C6) -> 0.018009901 | J6: =VALUE(D6) -> 0.02 | K6: =VALUE(E6) -> 0.036 | L6: =VALUE(F6) -> 0.019 | M6: =M5+1 -> 5 | N6: =SUM(G$2:G6) -> 0.11873507 | O6: =O5+1 -> 5 | P6: =SUM(H$2:H6) -> 0.061190844 | Q6: =Q5+1 -> 5 | R6: =SUM(I$2:I6) -> 0.069549084 | S6: =S5+1 -> 5 | T6: =SUM(J$2:J6) -> 0.07 | U6: =U5+1 -> 5 | V6: =SUM(K$2:K6) -> 0.159 | W6: 5 | X6: =SUM(L$2:L6) -> 0.092
A7: 0.0273284912109375 | B7: 0.015358924865722656 | C7: 0.018881797790527344 | D7: 0.02 | E7: 0.036 | F7: 0.02 | G7: =VALUE(A7) -> 0.027328491 | H7: 0.017042398 | I7: =VALUE(C7) -> 0.018881798 | J7: =VALUE(D7) -> 0.02 | K7: =VALUE(E7) -> 0.036 | L7: =VALUE(F7) -> 0.02 | M7: =M6+1 -> 6 | N7: =SUM(G$2:G7) -> 0.14606357 | O7: =O6+1 -> 6 | P7: =SUM(H$2:H7) -> 0.078233242 | Q7: =Q6+1 -> 6 | R7: =SUM(I$2:I7) -> 0.088430882 | S7: =S6+1 -> 6 | T7: =SUM(J$2:J7) -> 0.09 | U7: =U6+1 -> 6 | V7: =SUM(K$2:K7) -> 0.195 | W7: 6 | X7: =SUM(L$2:L7) -> 0.112
A8: 0.027365922927856445 | B8: 0.01582789421081543 | C8: 0.019309043884277344 | D8: 0.02 | E8: 0.038 | F8: 0.02 | G8: =VALUE(A8) -> 0.027365923 | H8: 0.017447472 | I8: =VALUE(C8) -> 0.019309044 | J8: =VALUE(D8) -> 0.02 | K8: =VALUE(E8) -> 0.038 | L8: =VALUE(F8) -> 0.02 | M8: =M7+1 -> 7 | N8: =SUM(G$2:G8) -> 0.17342949 | O8: =O7+1 -> 7 | P8: =SUM(H$2:H8) -> 0.095680714 | Q8: =Q7+1 -> 7 | R8: =SUM(I$2:I8) -> 0.10773993 | S8: =S7+1 -> 7 | T8: =SUM(J$2:J8) -> 0.11 | U8: =U7+1 -> 7 | V8: =SUM(K$2:K8) -> 0.233 | W8: 7 | X8: =SUM(L$2:L8) -> 0.132
A9: 0.027506589889526367 | B9: 0.017138004302978516 | C9: 0.020095109939575195 | D9: 0.02 | E9: 0.038 | F9: 0.02 | G9: =VALUE(A9) -> 0.02750659 | H9: 0.018088341 | I9: =VALUE(C9) -> 0.02009511 | J9: =VALUE(D9) -> 0.02 | K9: =VALUE(E9) -> 0.038 | L9: =VALUE(F9) -> 0.02 | M9: =M8+1 -> 8 | N9: =SUM(G$2:G9) -> 0.20093608 | O9: =O8+1 -> 8 | P9: =SUM(H$2:H9) -> 0.11376905 | Q9: =Q8+1 -> 8 | R9: =SUM(I$2:I9) -> 0.12783504 | S9: =S8+1 -> 8 | T9: =SUM(J$2:J9) -> 0.13 | U9: =U8+1 -> 8 | V9: =SUM(K$2:K9) -> 0.271 | W9: 8 | X9: =SUM(L$2:L9) -> 0.152
A10: 0.02788376808166504 | B10: 0.01734185218811035 | C10: 0.021628379821777344 | D10: 0.02 | E10: 0.04 | F10: 0.022 | G10: =VALUE(A10) -> 0.027883768 | H10: 0.018536568 | I10: =VALUE(C10) -> 0.02162838 | J10: =VALUE(D10) -> 0.02 | K10: =VALUE(E10) -> 0.04 | L10: =VALUE(F10) -> 0.022 | M10: =M9+1 -> 9 | N10: =SUM(G$2:G10) -> 0.22881985 | O10: =O9+1 -> 9 | P10: =SUM(H$2:H10) -> 0.13230562 | Q10: =Q9+1 -> 9 | R10: =SUM(I$2:I10) -> 0.14946342 | S10: =S9+1 -> 9 | T10: =SUM(J$2:J10) -> 0.15 | U10: =U9+1 -> 9 | V10: =SUM(K$2:K10) -> 0.311 | W10: 9 | X10: =SUM(L$2:L10) -> 0.174
A11: 0.0280914306640625 | B11: 0.017393827438354492 | C11: 0.026772022247314453 | D11: 0.02 | E11: 0.041 | F11: 0.022 | G11: =VALUE(A11) -> 0.028091431 | H11: 0.01864934 | I11: =VALUE(C11) -> 0.026772022 | J11: =VALUE(D11) -> 0.02 | K11: =VALUE(E11) -> 0.041 | L11: =VALUE(F11) -> 0.022 | M11: =M10+1 -> 10 | N11: =SUM(G$2:G11) -> 0.25691128 | O11: =O10+1 -> 10 | P11: =SUM(H$2:H11) -> 0.15095496 | Q11: =Q10+1 -> 10 | R11: =SUM(I$2:I11) -> 0.17623544 | S11: =S10+1 -> 10 | T11: =SUM(J$2:J11) -> 0.17 | U11: =U10+1 -> 10 | V11: =SUM(K$2:K11) -> 0.352 | W11: 10 | X11: =SUM(L$2:L11) -> 0.196
A12: 0.028391122817993164 | B12: 0.017560243606567383 | C12: 0.028182506561279297 | D12: 0.02 | E12: 0.042 | F12: 0.023 | G12: =VALUE(A12) -> 0.028391123 | H12: 0.01898098 | I12: =VALUE(C12) -> 0.028182507 | J12: =VALUE(D12) -> 0.02 | K12: =VALUE(E12) -> 0.042 | L12: =VALUE(F12) -> 0.023 | M12: =M11+1 -> 11 | N12: =SUM(G$2:G12) -> 0.2853024 | O12: =O11+1 -> 11 | P12: =SUM(H$2:H12) -> 0.16993594 | Q12: =Q11+1 -> 11 | R12: =SUM(I$2:I12) -> 0.20441794 | S12: =S11+1 -> 11 | T12: =SUM(J$2:J12) -> 0.19 | U12: =U11+1 -> 11 | V12: =SUM(K$2:K12) -> 0.394 | W12: 11 | X12: =SUM(L$2:L12) -> 0.219
A13: 0.04624581336975098 | B13: 0.018093585968017578 | C13: 0.028985023498535156 | D13: 0.02 | E13: 0.048 | F13: 0.027 | G13: =VALUE(A13) -> 0.046245813 | H13: 0.019583941 | I13: =VALUE(C13) -> 0.028985023 | J13: =VALUE(D13) -> 0.02 | K13: =VALUE(E13) -> 0.048 | L13: =VALUE(F13) -> 0.027 | M13: =M12+1 -> 12 | N13: =SUM(G$2:G13) -> 0.33154821 | O13: =O12+1 -> 12 | P13: =SUM(H$2:H13) -> 0.18951988 | Q13: =Q12+1 -> 12 | R13: =SUM(I$2:I13) -> 0.23340297 | S13: =S12+1 -> 12 | T13: =SUM(J$2:J13) -> 0.21 | U13: =U12+1 -> 12 | V13: =SUM(K$2:K13) -> 0.442 | W13: 12 | X13: =SUM(L$2:L13) -> 0.246
A14: 0.04707980155944824 | B14: 0.018942594528198242 | C14: 0.029070138931274414 | D14: 0.02 | E14: 0.048 | F14: 0.029 | G14: =VALUE(A14) -> 0.047079802 | H14: 0.019720793 | I14: =VALUE(C14) -> 0.029070139 | J14: =VALUE(D14) -> 0.02 | K14: =VALUE(E14) -> 0.048 | L14: =VALUE(F14) -> 0.029 | M14: =M13+1 -> 13 | N14: =SUM(G$2:G14) -> 0.37862802 | O14: =O13+1 -> 13 | P14: =SUM(H$2:H14) -> 0.20924067 | Q14: =Q13+1 -> 13 | R14: =SUM(I$2:I14) -> 0.26247311 | S14: =S13+1 -> 13 | T14: =SUM(J$2:J14) -> 0.23 | U14: =U13+1 -> 13 | V14: =SUM(K$2:K14) -> 0.49 | W14: 13 | X14: =SUM(L$2:L14) -> 0.275
... A74: 0.11025261878967285 | B74: 0.039472341537475586 | C74: 0.12228870391845703 | D74: 0.02 | E74: 0.259 | F74: 0.063 | G74: =VALUE(A74) -> 0.11025262 | H74: 0.043441772 | I74: =VALUE(C74) -> 0.1222887 | J74: =VALUE(D74) -> 0.02 | K74: =VALUE(E74) -> 0.259 | L74: =VALUE(F74) -> 0.063 | M74: =M73+1 -> 73 | N74: =SUM(G$2:G74) -> 5.6623533 | O74: =O73+1 -> 73 | P74: =SUM(H$2:H74) -> 2.0907364 | Q74: =Q73+1 -> 73 | R74: =SUM(I$2:I74) -> 4.2416358 | S74: =S73+1 -> 73 | T74: =SUM(J$2:J74) -> 1.43 | U74: =U73+1 -> 73 | V74: =SUM(K$2:K74) -> 7.172 | W74: 73 | X74: =SUM(L$2:L74) -> 3.254
A75: 0.11106038093566895 | B75: 0.039832115173339844 | C75: 0.12784075736999512 | D75: 0.02 | F75: 0.064 | G75: =VALUE(A75) -> 0.11106038 | H75: 0.043561459 | I75: =VALUE(C75) -> 0.12784076 | J75: =VALUE(D75) -> 0.02 | K75: =VALUE(E75) -> 0 | L75: =VALUE(F75) -> 0.064 | M75: =M74+1 -> 74 | N75: =SUM(G$2:G75) -> 5.7734137 | O75: =O74+1 -> 74 | P75: =SUM(H$2:H75) -> 2.1342978 | Q75: =Q74+1 -> 74 | R75: =SUM(I$2:I75) -> 4.3694766 | S75: =S74+1 -> 74 | T75: =SUM(J$2:J75) -> 1.45 | W75: 74 | X75: =SUM(L$2:L75) -> 3.318
A76: 0.1121363639831543 | B76: 0.03997325897216797 | C76: 0.13186955451965332 | D76: 0.02 | F76: 0.064 | G76: =VALUE(A76) -> 0.11213636 | H76: 0.044113874 | I76: =VALUE(C76) -> 0.13186955 | J76: =VALUE(D76) -> 0.02 | K76: =VALUE(E76) -> 0 | L76: =VALUE(F76) -> 0.064 | M76: =M75+1 -> 75 | N76: =SUM(G$2:G76) -> 5.88555 | O76: =O75+1 -> 75 | P76: =SUM(H$2:H76) -> 2.1784117 | Q76: =Q75+1 -> 75 | R76: =SUM(I$2:I76) -> 4.5013461 | S76: =S75+1 -> 75 | T76: =SUM(J$2:J76) -> 1.47 | W76: 75 | X76: =SUM(L$2:L76) -> 3.382
A77: 0.11243581771850586 | B77: 0.040471792221069336 | C77: 0.13216042518615723 | D77: 0.02 | F77: 0.064 | G77: =VALUE(A77) -> 0.11243582 | H77: 0.044621468 | I77: =VALUE(C77) -> 0.13216043 | J77: =VALUE(D77) -> 0.02 | K77: =VALUE(E77) -> 0 | L77: =VALUE(F77) -> 0.064 | M77: =M76+1 -> 76 | N77: =SUM(G$2:G77) -> 5.9979858 | O77: =O76+1 -> 76 | P77: =SUM(H$2:H77) -> 2.2230332 | Q77: =Q76+1 -> 76 | R77: =SUM(I$2:I77) -> 4.6335065 | S77: =S76+1 -> 76 | T77: =SUM(J$2:J77) -> 1.49 | W77: 76 | X77: =SUM(L$2:L77) -> 3.446
A78: 0.11270833015441895 | B78: 0.0406496524810791 | C78: 0.1352379322052002 | D78: 0.02 | F78: 0.065 | G78: =VALUE(A78) -> 0.11270833 | H78: 0.045562744 | I78: =VALUE(C78) -> 0.13523793 | J78: =VALUE(D78) -> 0.02 | K78: =VALUE(E78) -> 0 | L78: =VALUE(F78) -> 0.065 | M78: =M77+1 -> 77 | N78: =SUM(G$2:G78) -> 6.1106942 | O78: =O77+1 -> 77 | P78: =SUM(H$2:H78) -> 2.2685959 | Q78: =Q77+1 -> 77 | R78: =SUM(I$2:I78) -> 4.7687445 | S78: =S77+1 -> 77 | T78: =SUM(J$2:J78) -> 1.51 | W78: 77 | X78: =SUM(L$2:L78) -> 3.511
A79: 0.11277222633361816 | B79: 0.04071354866027832 | C79: 0.1354689598083496 | D79: 0.02 | F79: 0.066 | G79: =VALUE(A79) -> 0.11277223 | H79: 0.045658588 | I79: =VALUE(C79) -> 0.13546896 | J79: =VALUE(D79) -> 0.02 | K79: =VALUE(E79) -> 0 | L79: =VALUE(F79) -> 0.066 | M79: =M78+1 -> 78 | N79: =SUM(G$2:G79) -> 6.2234664 | O79: =O78+1 -> 78 | P79: =SUM(H$2:H79) -> 2.3142545 | Q79: =Q78+1 -> 78 | R79: =SUM(I$2:I79) -> 4.9042134 | S79: =S78+1 -> 78 | T79: =SUM(J$2:J79) -> 1.53 | W79: 78 | X79: =SUM(L$2:L79) -> 3.577
A80: 0.11479640007019043 | B80: 0.0417323112487793 | C80: 0.1374812126159668 | D80: 0.02 | F80: 0.066 | G80: =VALUE(A80) -> 0.1147964 | H80: 0.045875549 | I80: =VALUE(C80) -> 0.13748121 | J80: =VALUE(D80) -> 0.02 | K80: =VALUE(E80) -> 0 | L80: =VALUE(F80) -> 0.066 | M80: =M79+1 -> 79 | N80: =SUM(G$2:G80) -> 6.3382628 | O80: =O79+1 -> 79 | P80: =SUM(H$2:H80) -> 2.3601301 | Q80: =Q79+1 -> 79 | R80: =SUM(I$2:I80) -> 5.0416946 | S80: =S79+1 -> 79 | T80: =SUM(J$2:J80) -> 1.55 | W80: 79 | X80: =SUM(L$2:L80) -> 3.643
A81: 0.11705470085144043 | B81: 0.04183816909790039 | C81: 0.14122438430786133 | D81: 0.03 | F81: 0.066 | G81: =VALUE(A81) -> 0.1170547 | H81: 0.046022415 | I81: =VALUE(C81) -> 0.14122438 | J81: =VALUE(D81) -> 0.03 | K81: =VALUE(E81) -> 0 | L81: =VALUE(F81) -> 0.066 | M81: =M80+1 -> 80 | N81: =SUM(G$2:G81) -> 6.4553175 | O81: =O80+1 -> 80 | P81: =SUM(H$2:H81) -> 2.4061525 | Q81: =Q80+1 -> 80 | R81: =SUM(I$2:I81) -> 5.182919 | S81: =S80+1 -> 80 | T81: =SUM(J$2:J81) -> 1.58 | W81: 80 | X81: =SUM(L$2:L81) -> 3.709
A82: 0.11724662780761719 | B82: 0.043627023696899414 | C82: 0.14688587188720703 | D82: 0.03 | F82: 0.066 | G82: =VALUE(A82) -> 0.11724663 | H82: 0.046781778 | I82: =VALUE(C82) -> 0.14688587 | J82: =VALUE(D82) -> 0.03 | K82: =VALUE(E82) -> 0 | L82: =VALUE(F82) -> 0.066 | M82: =M81+1 -> 81 | N82: =SUM(G$2:G82) -> 6.5725641 | O82: =O81+1 -> 81 | P82: =SUM(H$2:H82) -> 2.4529343 | Q82: =Q81+1 -> 81 | R82: =SUM(I$2:I82) -> 5.3298049 | S82: =S81+1 -> 81 | T82: =SUM(J$2:J82) -> 1.61 | W82: 81 | X82: =SUM(L$2:L82) -> 3.775
A83: 0.11812043190002441 | B83: 0.04478716850280762 | C83: 0.14750194549560547 | D83: 0.03 | F83: 0.066 | G83: =VALUE(A83) -> 0.11812043 | H83: 0.047571421 | I83: =VALUE(C83) -> 0.14750195 | J83: =VALUE(D83) -> 0.03 | K83: =VALUE(E83) -> 0 | L83: =VALUE(F83) -> 0.066 | M83: =M82+1 -> 82 | N83: =SUM(G$2:G83) -> 6.6906846 | O83: =O82+1 -> 82 | P83: =SUM(H$2:H83) -> 2.5005057 | Q83: =Q82+1 -> 82 | R83: =SUM(I$2:I83) -> 5.4773068 | S83: =S82+1 -> 82 | T83: =SUM(J$2:J83) -> 1.64 | W83: 82 | X83: =SUM(L$2:L83) -> 3.841
A84: 0.11826467514038086 | B84: 0.04533576965332031 | C84: 0.14983844757080078 | D84: 0.03 | F84: 0.066 | G84: =VALUE(A84) -> 0.11826468 | H84: 0.048160076 | I84: =VALUE(C84) -> 0.14983845 | J84: =VALUE(D84) -> 0.03 | K84: =VALUE(E84) -> 0 | L84: =VALUE(F84) -> 0.066 | M84: =M83+1 -> 83 | N84: =SUM(G$2:G84) -> 6.8089492 | O84: =O83+1 -> 83 | P84: =SUM(H$2:H84) -> 2.5486658 | Q84: =Q83+1 -> 83 | R84: =SUM(I$2:I84) -> 5.6271453 | S84: =S83+1 -> 83 | T84: =SUM(J$2:J84) -> 1.67 | W84: 83 | X84: =SUM(L$2:L84) -> 3.907
A85: 0.11856913566589355 | B85: 0.04568004608154297 | C85: 0.15064501762390137 | D85: 0.03 | F85: 0.066 | G85: =VALUE(A85) -> 0.11856914 | H85: 0.048193216 | I85: =VALUE(C85) -> 0.15064502 | J85: =VALUE(D85) -> 0.03 | K85: =VALUE(E85) -> 0 | L85: =VALUE(F85) -> 0.066 | M85: =M84+1 -> 84 | N85: =SUM(G$2:G85) -> 6.9275184 | O85: =O84+1 -> 84 | P85: =SUM(H$2:H85) -> 2.596859 | Q85: =Q84+1 -> 84 | R85: =SUM(I$2:I85) -> 5.7777903 | S85: =S84+1 -> 84 | T85: =SUM(J$2:J85) -> 1.7 | W85: 84 | X85: =SUM(L$2:L85) -> 3.973
A86: 0.11860203742980957 | B86: 0.04596281051635742 | C86: 0.15144896507263184 | D86: 0.03 | F86: 0.066 | G86: =VALUE(A86) -> 0.11860204 | H86: 0.049321651 | I86: =VALUE(C86) -> 0.15144897 | J86: =VALUE(D86) -> 0.03 | K86: =VALUE(E86) -> 0 | L86: =VALUE(F86) -> 0.066 | M86: =M85+1 -> 85 | N86: =SUM(G$2:G86) -> 7.0461204 | O86: =O85+1 -> 85 | P86: =SUM(H$2:H86) -> 2.6461806 | Q86: =Q85+1 -> 85 | R86: =SUM(I$2:I86) -> 5.9292393 | S86: =S85+1 -> 85 | T86: =SUM(J$2:J86) -> 1.73 | W86: 85 | X86: =SUM(L$2:L86) -> 4.039
... A323: 0.19126105308532715 | B323: 0.07379341125488281 | C323: 0.7296640872955322 | D323: 18.41 | F323: 0.258 | G323: =VALUE(A323) -> 0.19126105 | H323: 0.079154968 | I323: =VALUE(C323) -> 0.72966409 | J323: =VALUE(D323) -> 18.41 | K323: =VALUE(E323) -> 0 | L323: =VALUE(F323) -> 0.258 | M323: =M322+1 -> 322 | N323: =SUM(G$2:G323) -> 44.686048 | O323: =O322+1 -> 322 | P323: =SUM(H$2:H323) -> 17.556059 | Q323: =Q322+1 -> 322 | R323: =SUM(I$2:I323) -> 105.40016 | S323: =S322+1 -> 322 | T323: =SUM(J$2:J323) -> 788.61 | W323: 322 | X323: =SUM(L$2:L323) -> 32.767
A324: 0.19129586219787598 | B324: 0.0738978385925293 | C324: 0.7297658920288086 | D324: 19.28 | G324: =VALUE(A324) -> 0.19129586 | H324: 0.079311848 | I324: =VALUE(C324) -> 0.72976589 | J324: =VALUE(D324) -> 19.28 | K324: =VALUE(E324) -> 0 | L324: =VALUE(F324) -> 0 | M324: =M323+1 -> 323 | N324: =SUM(G$2:G324) -> 44.877344 | O324: =O323+1 -> 323 | P324: =SUM(H$2:H324) -> 17.635371 | Q324: =Q323+1 -> 323 | R324: =SUM(I$2:I324) -> 106.12993 | S324: =S323+1 -> 323 | T324: =SUM(J$2:J324) -> 807.89
A325: 0.19141769409179688 | B325: 0.07420992851257324 | C325: 0.7300868034362793 | D325: 19.54 | G325: =VALUE(A325) -> 0.19141769 | H325: 0.079439163 | I325: =VALUE(C325) -> 0.7300868 | J325: =VALUE(D325) -> 19.54 | K325: =VALUE(E325) -> 0 | L325: =VALUE(F325) -> 0 | M325: =M324+1 -> 324 | N325: =SUM(G$2:G325) -> 45.068761 | O325: =O324+1 -> 324 | P325: =SUM(H$2:H325) -> 17.71481 | Q325: =Q324+1 -> 324 | R325: =SUM(I$2:I325) -> 106.86001 | S325: =S324+1 -> 324 | T325: =SUM(J$2:J325) -> 827.43
A326: 0.19152331352233887 | B326: 0.07477355003356934 | C326: 0.7301974296569824 | D326: 19.74 | G326: =VALUE(A326) -> 0.19152331 | H326: 0.079552889 | I326: =VALUE(C326) -> 0.73019743 | J326: =VALUE(D326) -> 19.74 | K326: =VALUE(E326) -> 0 | L326: =VALUE(F326) -> 0 | M326: =M325+1 -> 325 | N326: =SUM(G$2:G326) -> 45.260285 | O326: =O325+1 -> 325 | P326: =SUM(H$2:H326) -> 17.794363 | Q326: =Q325+1 -> 325 | R326: =SUM(I$2:I326) -> 107.59021 | S326: =S325+1 -> 325 | T326: =SUM(J$2:J326) -> 847.17
A327: 0.19175028800964355 | B327: 0.07477736473083496 | C327: 0.7328064441680908 | D327: 19.94 | G327: =VALUE(A327) -> 0.19175029 | H327: 0.079740286 | I327: =VALUE(C327) -> 0.73280644 | J327: =VALUE(D327) -> 19.94 | K327: =VALUE(E327) -> 0 | L327: =VALUE(F327) -> 0 | M327: =M326+1 -> 326 | N327: =SUM(G$2:G327) -> 45.452035 | O327: =O326+1 -> 326 | P327: =SUM(H$2:H327) -> 17.874103 | Q327: =Q326+1 -> 326 | R327: =SUM(I$2:I327) -> 108.32302 | S327: =S326+1 -> 326 | T327: =SUM(J$2:J327) -> 867.11
A328: 0.19175982475280762 | B328: 0.07491207122802734 | C328: 0.732893705368042 | D328: 2.00 | G328: =VALUE(A328) -> 0.19175982 | H328: 0.07974124 | I328: =VALUE(C328) -> 0.73289371 | J328: =VALUE(D328) -> 2 | K328: =VALUE(E328) -> 0 | L328: =VALUE(F328) -> 0 | M328: =M327+1 -> 327 | N328: =SUM(G$2:G328) -> 45.643795 | O328: =O327+1 -> 327 | P328: =SUM(H$2:H328) -> 17.953845 | Q328: =Q327+1 -> 327 | R328: =SUM(I$2:I328) -> 109.05591 | S328: =S327+1 -> 327 | T328: =SUM(J$2:J328) -> 869.11
A329: 0.19208431243896484 | B329: 0.07501101493835449 | C329: 0.7341086864471436 | D329: 2.02 | G329: =VALUE(A329) -> 0.19208431 | H329: 0.079927206 | I329: =VALUE(C329) -> 0.73410869 | J329: =VALUE(D329) -> 2.02 | K329: =VALUE(E329) -> 0 | L329: =VALUE(F329) -> 0 | M329: =M328+1 -> 328 | N329: =SUM(G$2:G329) -> 45.835879 | O329: =O328+1 -> 328 | P329: =SUM(H$2:H329) -> 18.033772 | Q329: =Q328+1 -> 328 | R329: =SUM(I$2:I329) -> 109.79002 | S329: =S328+1 -> 328 | T329: =SUM(J$2:J329) -> 871.13
A330: 0.19257545471191406 | B330: 0.0751035213470459 | C330: 0.7343063354492188 | D330: 2.06 | G330: =VALUE(A330) -> 0.19257545 | H330: 0.080256701 | I330: =VALUE(C330) -> 0.73430634 | J330: =VALUE(D330) -> 2.06 | K330: =VALUE(E330) -> 0 | L330: =VALUE(F330) -> 0 | M330: =M329+1 -> 329 | N330: =SUM(G$2:G330) -> 46.028455 | O330: =O329+1 -> 329 | P330: =SUM(H$2:H330) -> 18.114028 | Q330: =Q329+1 -> 329 | R330: =SUM(I$2:I330) -> 110.52433 | S330: =S329+1 -> 329 | T330: =SUM(J$2:J330) -> 873.19
A331: 0.19283533096313477 | B331: 0.07581567764282227 | C331: 0.7346699237823486 | D331: 2.06 | G331: =VALUE(A331) -> 0.19283533 | H331: 0.080788851 | I331: =VALUE(C331) -> 0.73466992 | J331: =VALUE(D331) -> 2.06 | K331: =VALUE(E331) -> 0 | L331: =VALUE(F331) -> 0 | M331: =M330+1 -> 330 | N331: =SUM(G$2:G331) -> 46.22129 | O331: =O330+1 -> 330 | P331: =SUM(H$2:H331) -> 18.194817 | Q331: =Q330+1 -> 330 | R331: =SUM(I$2:I331) -> 111.259 | S331: =S330+1 -> 330 | T331: =SUM(J$2:J331) -> 875.25
A332: 0.19290852546691895 | B332: 0.07588601112365723 | C332: 0.7349710464477539 | D332: 2.07 | G332: =VALUE(A332) -> 0.19290853 | H332: 0.081713438 | I332: =VALUE(C332) -> 0.73497105 | J332: =VALUE(D332) -> 2.07 | K332: =VALUE(E332) -> 0 | L332: =VALUE(F332) -> 0 | M332: =M331+1 -> 331 | N332: =SUM(G$2:G332) -> 46.414198 | O332: =O331+1 -> 331 | P332: =SUM(H$2:H332) -> 18.276531 | Q332: =Q331+1 -> 331 | R332: =SUM(I$2:I332) -> 111.99397 | S332: =S331+1 -> 331 | T332: =SUM(J$2:J332) -> 877.32
A333: 0.19323229789733887 | B333: 0.07588696479797363 | C333: 0.7357780933380127 | D333: 2.09 | G333: =VALUE(A333) -> 0.1932323 | H333: 0.082881212 | I333: =VALUE(C333) -> 0.73577809 | J333: =VALUE(D333) -> 2.09 | K333: =VALUE(E333) -> 0 | L333: =VALUE(F333) -> 0 | M333: =M332+1 -> 332 | N333: =SUM(G$2:G333) -> 46.607431 | O333: =O332+1 -> 332 | P333: =SUM(H$2:H333) -> 18.359412 | Q333: =Q332+1 -> 332 | R333: =SUM(I$2:I333) -> 112.72975 | S333: =S332+1 -> 332 | T333: =SUM(J$2:J333) -> 879.41
A334: 0.1935255527496338 | B334: 0.07641363143920898 | C334: 0.736868143081665 | D334: 2.24 | G334: =VALUE(A334) -> 0.19352555 | H334: 0.083092928 | I334: =VALUE(C334) -> 0.73686814 | J334: =VALUE(D334) -> 2.24 | K334: =VALUE(E334) -> 0 | L334: =VALUE(F334) -> 0 | M334: =M333+1 -> 333 | N334: =SUM(G$2:G334) -> 46.800956 | O334: =O333+1 -> 333 | P334: =SUM(H$2:H334) -> 18.442505 | Q334: =Q333+1 -> 333 | R334: =SUM(I$2:I334) -> 113.46661 | S334: =S333+1 -> 333 | T334: =SUM(J$2:J334) -> 881.65
A335: 0.1935279369354248 | B335: 0.07644963264465332 | C335: 0.7379758358001709 | D335: 2.25 | G335: =VALUE(A335) -> 0.19352794 | H335: 0.083155155 | I335: =VALUE(C335) -> 0.73797584 | J335: =VALUE(D335) -> 2.25 | K335: =VALUE(E335) -> 0 | L335: =VALUE(F335) -> 0 | M335: =M334+1 -> 334 | N335: =SUM(G$2:G335) -> 46.994484 | O335: =O334+1 -> 334 | P335: =SUM(H$2:H335) -> 18.52566 | Q335: =Q334+1 -> 334 | R335: =SUM(I$2:I335) -> 114.20459 | S335: =S334+1 -> 334 | T335: =SUM(J$2:J335) -> 883.9
...

Sheet cvc5 predicates mbqi
A1: answer | B1: duration
A2: timeout | B2: 20
A3: timeout | B3: 20
A4: timeout | B4: 20
A5: timeout | B5: 20
A6: timeout | B6: 20
A7: sat | B7: 0.017
A8: sat | B8: 0.018
A9: sat | B9: 0.019
A10: timeout | B10: 20
A11: sat | B11: 0.019
A12: timeout | B12: 20
A13: timeout | B13: 20
... A1363: unsat | B1363: 0.258

Sheet cvc5 predicates
A1: answer | B1: duration
A2: unknown | B2: 0.065
A3: unknown | B3: 0.052
A4: unknown | B4: 0.075
A5: unknown | B5: 0.056
A6: unknown | B6: 0.062
A7: unsat | B7: 0.022
A8: unsat | B8: 0.032
A9: unsat | B9: 0.033
A10: unknown | B10: 0.062
A11: unsat | B11: 0.036
A12: unknown | B12: 0.111
A13: unknown | B13: 0.057
... A1363: unsat | B1363: 0.259

Sheet Sheet1

Sheet z3 predicates
A1: file | B1: answer | C1: duration
A2: test1_redundant_analysis_2.smt2 | B2: unsat | C2: 0.01
A3: test2_conflict_analysis_2.smt2 | B3: unsat | C3: 0.01
A4: test2_conflict_analysis_0.smt2 | B4: unsat | C4: 0.01
A5: CSI-corrected_concern_analysis_6.smt2 | B5: unsat | C5: 0.02
A6: ALMI_concern_analysis_5.smt2 | B6: unsat | C6: 0.02
A7: test_redundant_analysis_14.smt2 | B7: unsat | C7: 0.02
A8: safescade_redundant_analysis_4.smt2 | B8: unsat | C8: 0.02
A9: test3_redundant_analysis_1.smt2 | B9: sat | C9: 0.02
A10: Autocar_concern_analysis_7.smt2 | B10: unsat | C10: 0.02
A11: buggy_redundant_analysis_0.smt2 | B11: unsat | C11: 0.02
A12: test4_redundant_analysis_1.smt2 | B12: sat | C12: 0.02
... A1363: BSN_redundant_analysis_8.smt2 | B1363: unknown | C1363: 9.97
